Workbook

Sheet Borrower Overview
A1: Borrower Overview
A2: Company | B2: Company ID | C2: Industry | D2: Primary NAICS | E2: Website | F2: Primary Contact | G2: Primary Contact Phone | H2: Primary Contact Email | I2: Update Interval | J2: Current Update | K2: Previous Update | L2: Next Update | M2: Lender | N2: Lender ID | O2: Specific Individual | P2: Specific ID
A3: BrightNest Consumer Brands | B3: 987654321 | C3: Consumer Goods | D3: 448410 | E3: www.brightnest.com | F3: Billy Bob | G3: 401-321-7654 | H3: bbob@DEF.com | I3: Monthly | J3: 45989 | K3: 45961 | L3: 46022 | M3: J.P. Morgan Chase | N3: 67891 | O3: Alex Parisi | P3: 000456

Sheet Collateral Overview
A1: Main Type | B1: SubType | C1: Beginning Collateral | D1: Ineligibles | E1: Eligible Collateral | F1: NOLV % | G1: Dilution Rate | H1: Advanced Rate | I1: Rate Limit | J1: Utilized Rate | K1: Pre-Reserve Collateral | L1: Reserves | M1: Net Collateral
A2: Accounts Receivable | B2: =A2 -> Accounts Receivable | C2: 24026412 | D2: -2599691.5 | E2: =C2+D2 -> 21426721 | F2: 0.9 | G2: 1 | H2: =F2*G2 -> 0.9 | I2: ='Collateral Limits '!E2 -> 0.9 | J2: =H2 -> 0.9 | K2: =E2*J2 -> 19284049 | L2: -1748856.9 | M2: =K2+L2 -> 17535192
A3: Inventory | B3: Finished Goods | C3: =FG_Inventory_Metrics!D49 -> 17244592 | D3: =-FG_Inventory_Metrics!E49 -> -1379567.4 | E3: =C3+D3 -> 15865024 | F3: =NOLV_Table!E22 -> 0.64271712 | G3: 0.85 | H3: =F3*G3 -> 0.54630955 | I3: ='Collateral Limits '!E3 -> 1 | J3: =H3 -> 0.54630955 | K3: =E3*J3 -> 8667214.3 | L3: 0 | M3: =K3+L3 -> 8667214.3
A4: Inventory | B4: Raw Materials | C4: =RM_Inventory_Metrics!D49 -> 8427622.3 | D4: =-RM_Inventory_Metrics!E49 -> -1531374.2 | E4: =C4+D4 -> 6896248.2 | F4: =NOLV_Table!G22 -> 0.26688734 | G4: 0.85 | H4: =F4*G4 -> 0.22685424 | I4: ='Collateral Limits '!E5 -> 0.5 | J4: =H4 -> 0.22685424 | K4: =E4*J4 -> 1564443.1 | L4: 0 | M4: =K4+L4 -> 1564443.1
A5: Inventory | B5: Work-In-Process | C5: =WIP_Inventory_Metrics!D49 -> 2964502.2 | D5: =-WIP_Inventory_Metrics!E49 -> -507920.76 | E5: =C5+D5 -> 2456581.5 | F5: =NOLV_Table!I22 -> 0.10378389 | G5: 0.85 | H5: =F5*G5 -> 0.088216307 | I5: ='Collateral Limits '!E4 -> 0.4 | J5: =H5 -> 0.088216307 | K5: =E5*J5 -> 216710.55 | L5: 0 | M5: =K5+L5 -> 216710.55
A6: Other Collateral | B6: Machinery And Equipment | C6: =E6-D6 -> 22120000 | D6: -2250000 | E6: 19870000 | F6: 0.8 | G6: 1 | H6: =F6*G6 -> 0.8 | I6: 0.85 | J6: =H6 -> 0.8 | K6: =E6*J6 -> 15896000 | L6: 0 | M6: =K6+L6 -> 15896000

Sheet Machinery & Equipment >>>

Sheet Machinery & Equipment 
A1: Equipment Type | B1: Manufacturer | C1: Serial Number | D1: Year | E1: Condition | F1: Fair Market Value | G1: Orderly Liquidation Value | J1: Total Asset Count | K1: Total Fair Market Value | L1: Total Orderly Liquidation Value
A2: Ribbon Blender | B2: Munson | C2: MUNS-85013 | D2: 2019 | E2: Good | F2: 319810 | G2: 248940 | J2: =COUNTA(A2:A65) -> 64 | K2: =SUM(F2:F65) -> 26415030 | L2: =SUM(G2:G65) -> 19870000
A3: Mixing Kettle | B3: Lee | C3: LEE-93336 | D3: 2021 | E3: Good | F3: 845620 | G3: 631890
A4: High-Shear Mixer | B4: Silverson | C4: SILV-27243 | D4: 2019 | E4: Very Good | F4: 611090 | G4: 486520
A5: Dry Ingredient Sifter | B5: Kason | C5: KASO-93253 | D5: 2020 | E5: Very Good | F5: 553600 | G5: 397900
A6: Extrusion Line | B6: Baker Perkins | C6: BAKE-16383 | D6: 2019 | E6: Very Good | F6: 128840 | G6: 103700
A7: Shaping Line | B7: Clextral | C7: CLEX-79804 | D7: 2017 | E7: Very Good | F7: 148170 | G7: 103680
A8: Color Injection System | B8: ColorBlend | C8: COLO-84638 | D8: 2017 | E8: Very Good | F8: 53480 | G8: 38610
A9: Cooling Tunnel | B9: Sollich | C9: SOLL-71525 | D9: 2017 | E9: Very Good | F9: 729920 | G9: 575700
A10: Conveyor System | B10: Dorner | C10: DORN-76622 | D10: 2020 | E10: Very Good | F10: 490770 | G10: 399530
A11: Dust Collector | B11: Camfil | C11: CAMF-74351 | D11: 2018 | E11: Good | F11: 656060 | G11: 470620
A12: Bottling Line | B12: Krones | C12: KR-275622 | D12: 2017 | E12: Good | F12: 18770 | G12: 13680
A13: Form-Fill-Seal Machine | B13: Bosch | C13: BO-751539 | D13: 2017 | E13: Very Good | F13: 887260 | G13: 644650
A14: Labeling System | B14: Avery | C14: AVER-25096 | D14: 2017 | E14: Good | F14: 766290 | G14: 553280
... A65: Cooling Tunnel | B65: Sollich | C65: SOLL-67793 | D65: 2021 | E65: Good | F65: 332740 | G65: 237120

Sheet Accounts Receivable >>>

Sheet Aging Composition
A1: Division | B1: AsOfDate | C1: Bucket | D1: PctOfTotal | E1: Amount
A2: Retail Brands | B2: 45657 | C2: Current | D2: 0.779 | E2: 6021670
A3: Retail Brands | B3: 45657 | C3: 1-30 | D3: 0.080363636 | E3: 621210.91
A4: Retail Brands | B4: 45657 | C4: 31-60 | D4: 0.060272727 | E4: 465908.18
A5: Retail Brands | B5: 45657 | C5: 61-90 | D5: 0.040181818 | E5: 310605.45
A6: Retail Brands | B6: 45657 | C6: 90+ | D6: 0.040181819 | E6: 310605.46
A7: Retail Brands | B7: 45688 | C7: Current | D7: 0.776 | E7: 5887512
A8: Retail Brands | B8: 45688 | C8: 1-30 | D8: 0.081454546 | E8: 617995.64
A9: Retail Brands | B9: 45688 | C9: 31-60 | D9: 0.061090909 | E9: 463496.73
A10: Retail Brands | B10: 45688 | C10: 61-90 | D10: 0.040727273 | E10: 308997.82
A11: Retail Brands | B11: 45688 | C11: 90+ | D11: 0.040727272 | E11: 308997.81
A12: Retail Brands | B12: 45716 | C12: Current | D12: 0.775 | E12: 5913250
A13: Retail Brands | B13: 45716 | C13: 1-30 | D13: 0.081818182 | E13: 624272.73
... A241: All Divisions | B241: 45991 | C241: Current | D241: 0.80917208 | E241: 14455050

Sheet AR_Metrics
A1: Division | B1: AsOfDate | C1: Balance | D1: DSO | E1: PctPastDue | F1: CurrentAmt | G1: PastDueAmt
A2: All Divisions | B2: 45657 | C2: 17247000 | D2: 40 | E2: 0.192 | F2: 13942681 | G2: 3304319
A3: All Divisions | B3: 45688 | C3: 17082000 | D3: 42.8 | E3: 0.194 | F3: 13766204 | G3: 3315796
A4: All Divisions | B4: 45716 | C4: 17284000 | D4: 43.6 | E4: 0.194 | F4: 13922854 | G4: 3361146
A5: All Divisions | B5: 45747 | C5: 17156000 | D5: 43.1 | E5: 0.191 | F5: 13875606 | G5: 3280394
A6: All Divisions | B6: 45777 | C6: 17476000 | D6: 43 | E6: 0.188 | F6: 14189791 | G6: 3286209
A7: All Divisions | B7: 45808 | C7: 17294000 | D7: 42.8 | E7: 0.189 | F7: 14018960 | G7: 3275040
A8: All Divisions | B8: 45838 | C8: 17705000 | D8: 44.2 | E8: 0.19 | F8: 14336595 | G8: 3368405
A9: All Divisions | B9: 45869 | C9: 17631000 | D9: 46.5 | E9: 0.193 | F9: 14223586 | G9: 3407414
A10: All Divisions | B10: 45900 | C10: 17686000 | D10: 45.6 | E10: 0.194 | F10: 14262196 | G10: 3423804
A11: All Divisions | B11: 45930 | C11: 17851000 | D11: 42.8 | E11: 0.196 | F11: 14360273 | G11: 3490727
A12: All Divisions | B12: 45961 | C12: 18063000 | D12: 44.4 | E12: 0.197 | F12: 14496656 | G12: 3566344
A13: All Divisions | B13: 45991 | C13: 17864000 | D13: 46.8 | E13: 0.191 | F13: 14455050 | G13: 3408950
... A49: Retail Brands | B49: 45991 | C49: 7835000 | D49: 54.2 | E49: 0.22 | F49: 6111300 | G49: 1723700

Sheet Top20_By_Total_AR
A1: Division | B1: AsOfDate | C1: Customer | D1: Current | E1: 0-30 | F1: 31-60 | G1: 61-90 | H1: 91+ | I1: TotalAR | J1: CoveragePctOfDivisionAR
A2: All Divisions | B2: 45657 | C2: CloverLane Foods | D2: 574172.79 | E2: 54431.83 | F2: 4497.21 | G2: 22526.02 | H2: 32310.08 | I2: 687937.93 | J2: 0.51907707
A3: All Divisions | B3: 45657 | C3: Crown Confections | D3: 313818.36 | E3: 37362.09 | F3: 12409.61 | G3: 4179.57 | H3: 18935.17 | I3: 386704.8 | J3: 0.51907707
A4: All Divisions | B4: 45657 | C4: Crescent Confections | D4: 517234.58 | E4: 34883.45 | F4: 30241.51 | G4: 49766.88 | H4: 6015.85 | I4: 638142.26 | J4: 0.51907707
A5: All Divisions | B5: 45657 | C5: Celebration Ingredients | D5: 668724.07 | E5: 56713.78 | F5: 34858.77 | G5: 93482.53 | H5: 8869.74 | I5: 862648.89 | J5: 0.51907707
A6: All Divisions | B6: 45657 | C6: SugarRush Brands | D6: 395302.47 | E6: 22656.81 | F6: 16491 | G6: 31189.66 | H6: 9347.64 | I6: 474987.58 | J6: 0.51907707
A7: All Divisions | B7: 45657 | C7: Summit Crest Baking | D7: 372937.59 | E7: 32417.39 | F7: 18066.74 | G7: 18246.83 | H7: 351.55 | I7: 442020.09 | J7: 0.51907707
A8: All Divisions | B8: 45657 | C8: Everyday Baking Depot | D8: 48640.95 | E8: 5876.95 | F8: 7331.69 | G8: 1503.26 | H8: 200.83 | I8: 63553.68 | J8: 0.51907707
A9: All Divisions | B9: 45657 | C9: Lighthouse Grocery Partners | D9: 190302.03 | E9: 16650.93 | F9: 6263.19 | G9: 15325.97 | H9: 8238.12 | I9: 236780.24 | J9: 0.51907707
A10: All Divisions | B10: 45657 | C10: Premium Dessert Partners | D10: 325646 | E10: 32574.68 | F10: 2444.29 | G10: 76651.79 | H10: 3611.37 | I10: 440928.13 | J10: 0.51907707
A11: All Divisions | B11: 45657 | C11: Frontier Foodservice | D11: 481310.22 | E11: 66347.07 | F11: 15544.37 | G11: 32226.15 | H11: 3696.21 | I11: 599124.02 | J11: 0.51907707
A12: All Divisions | B12: 45657 | C12: Factory Direct Baking | D12: 525261.6 | E12: 75004.96 | F12: 46878.82 | G12: 10870.02 | H12: 50933.5 | I12: 708948.9 | J12: 0.51907707
A13: All Divisions | B13: 45657 | C13: SweetTreat Markets | D13: 267815.42 | E13: 14758.84 | F13: 39137.52 | G13: 5765.38 | H13: 8537.12 | I13: 336014.29 | J13: 0.51907707
... A961: Retail Brands | B961: 45991 | C961: Silverline Retail Foods | D961: 127832.78 | E961: 9748.96 | F961: 10194.14 | G961: 9077.55 | H961: 2349.57 | I961: 159203 | J961: 0.6546637

Sheet Top20_By_PastDue
A1: Division | B1: AsOfDate | C1: Customer | D1: Current | E1: 0-30 | F1: 31-60 | G1: 61-90 | H1: 91+ | I1: TotalAR | J1: TotalPastDue | K1: CoveragePctOfDivisionPastDue
A2: All Divisions | B2: 45657 | C2: CloverLane Foods | D2: 56073.53 | E2: 51272.36 | F2: 57885.86 | G2: 27996.96 | H2: 2339.69 | I2: 195568.4 | J2: 139494.87 | K2: 0.73492511
A3: All Divisions | B3: 45657 | C3: Crown Confections | D3: 8186.17 | E3: 1215.62 | F3: 3473.55 | G3: 4249.23 | H3: 373.66 | I3: 17498.22 | J3: 9312.05 | K3: 0.73492511
A4: All Divisions | B4: 45657 | C4: Crescent Confections | D4: 164127.38 | E4: 74755.51 | F4: 101760.13 | G4: 34513.43 | H4: 21283.51 | I4: 396439.96 | J4: 232312.57 | K4: 0.73492511
A5: All Divisions | B5: 45657 | C5: Celebration Ingredients | D5: 96688.42 | E5: 45167.21 | F5: 38726.85 | G5: 92935.88 | H5: 15561.46 | I5: 289079.83 | J5: 192391.41 | K5: 0.73492511
A6: All Divisions | B6: 45657 | C6: SugarRush Brands | D6: 98605.38 | E6: 57456.7 | F6: 20266.04 | G6: 43299.44 | H6: 28545.25 | I6: 248172.81 | J6: 149567.43 | K6: 0.73492511
A7: All Divisions | B7: 45657 | C7: Summit Crest Baking | D7: 132378.29 | E7: 46786.16 | F7: 25506.98 | G7: 44417.29 | H7: 62131.79 | I7: 311220.51 | J7: 178842.22 | K7: 0.73492511
A8: All Divisions | B8: 45657 | C8: Everyday Baking Depot | D8: 21253.01 | E8: 8188.87 | F8: 11392.72 | G8: 19153.71 | H8: 5448.6 | I8: 65436.91 | J8: 44183.9 | K8: 0.73492511
A9: All Divisions | B9: 45657 | C9: Lighthouse Grocery Partners | D9: 64546.31 | E9: 44274.77 | F9: 9639.74 | G9: 11193.74 | H9: 7185.45 | I9: 136840.01 | J9: 72293.7 | K9: 0.73492511
A10: All Divisions | B10: 45657 | C10: Premium Dessert Partners | D10: 34442.46 | E10: 19509.72 | F10: 28273.55 | G10: 7687.09 | H10: 2428.03 | I10: 92340.85 | J10: 57898.4 | K10: 0.73492511
A11: All Divisions | B11: 45657 | C11: Frontier Foodservice | D11: 129506.03 | E11: 70460.88 | F11: 45604.6 | G11: 2584.4 | H11: 21411.72 | I11: 269567.63 | J11: 140061.6 | K11: 0.73492511
A12: All Divisions | B12: 45657 | C12: Factory Direct Baking | D12: 19108.84 | E12: 11662.68 | F12: 3994.74 | G12: 1961.62 | H12: 3977.06 | I12: 40704.95 | J12: 21596.11 | K12: 0.73492511
A13: All Divisions | B13: 45657 | C13: SweetTreat Markets | D13: 77771.64 | E13: 118797.81 | F13: 35617.77 | G13: 31963.76 | H13: 24074.06 | I13: 288225.04 | J13: 210453.4 | K13: 0.73492511
... A961: Retail Brands | B961: 45991 | C961: Silverline Retail Foods | D961: 16079.39 | E961: 6277.08 | F961: 3060.24 | G961: 10671.07 | H961: 7276.56 | I961: 43364.35 | J961: 27284.96 | K961: 0.71941022

Sheet Ineligible_Trend
A1: Date | B1: Division | C1: Total AR | D1: Total Ineligible | E1: Ineligible % of AR
A2: 45657 | B2: Retail Brands | C2: 7730000 | D2: 912348.47 | E2: 0.118
A3: 45688 | B3: Retail Brands | C3: 7587000 | D3: 1404198.2 | E3: 0.1851
A4: 45716 | B4: Retail Brands | C4: 7630000 | D4: 1004388.3 | E4: 0.1316
A5: 45747 | B5: Retail Brands | C5: 7623000 | D5: 1219331.9 | E5: 0.16
A6: 45777 | B6: Retail Brands | C6: 7815000 | D6: 1552585.2 | E6: 0.1987
A7: 45808 | B7: Retail Brands | C7: 7598000 | D7: 980342.33 | E7: 0.129
A8: 45838 | B8: Retail Brands | C8: 7958000 | D8: 1378982.4 | E8: 0.1733
A9: 45869 | B9: Retail Brands | C9: 7794000 | D9: 1058766.5 | E9: 0.1358
A10: 45900 | B10: Retail Brands | C10: 7916000 | D10: 1543488 | E10: 0.195
A11: 45930 | B11: Retail Brands | C11: 7907000 | D11: 1283174.9 | E11: 0.1623
A12: 45961 | B12: Retail Brands | C12: 8081000 | D12: 1331794.4 | E12: 0.1648
A13: 45991 | B13: Retail Brands | C13: 7835000 | D13: 1234450.1 | E13: 0.1576
... A49: 45991 | B49: All Divisions | C49: 17864000 | D49: 2738267 | E49: 0.1533

Sheet Ineligible_Overview
A1: Date | B1: Division | C1: Past Due >90 Days | D1: Dilution | E1: Cross Age | F1: Concentration Over Cap | G1: Foreign | H1: Government | I1: Intercompany | J1: Contra | K1: Other | L1: Total Ineligible | M1: Ineligible % of AR
A2: 45657 | B2: Retail Brands | C2: 310605.46 | D2: 1775.08 | E2: 56153.6 | F2: 116496.44 | G2: 49196.19 | H2: 59967.23 | I2: 1160.97 | J2: 60308.94 | K2: 256684.56 | L2: 912348.47 | M2: 0.118
A3: 45688 | B3: Retail Brands | C3: 308997.81 | D3: 206618.18 | E3: 18167.4 | F3: 354055.3 | G3: 307116.06 | H3: 28475.03 | I3: 157911.57 | J3: 3266.29 | K3: 19590.6 | L3: 1404198.2 | M3: 0.1851
A4: 45716 | B4: Retail Brands | C4: 312136.36 | D4: 21399.48 | E4: 177160.38 | F4: 212320.32 | G4: 52610.84 | H4: 47798.65 | I4: 14742.11 | J4: 10917.9 | K4: 155302.22 | L4: 1004388.3 | M4: 0.1316
A5: 45747 | B5: Retail Brands | C5: 309078 | D5: 5744.65 | E5: 65539.6 | F5: 51508.49 | G5: 188909.57 | H5: 126891.32 | I5: 92408.57 | J5: 80610.6 | K5: 298641.14 | L5: 1219331.9 | M5: 0.16
A6: 45777 | B6: Retail Brands | C6: 309758.19 | D6: 154061.05 | E6: 102417.74 | F6: 594394.9 | G6: 24572.63 | H6: 169353.89 | I6: 27108.27 | J6: 143665.77 | K6: 27252.76 | L6: 1552585.2 | M6: 0.1987
A7: 45808 | B7: Retail Brands | C7: 298394.19 | D7: 125523.35 | E7: 189604.24 | F7: 126494.62 | G7: 66344.37 | H7: 76960.95 | I7: 36070.53 | J7: 14867.43 | K7: 46082.65 | L7: 980342.33 | M7: 0.129
A8: 45838 | B8: Retail Brands | C8: 311085.46 | D8: 9052.49 | E8: 2919.97 | F8: 205163.86 | G8: 49700.87 | H8: 168341.77 | I8: 184914.62 | J8: 376532.39 | K8: 71270.99 | L8: 1378982.4 | M8: 0.1733
A9: 45869 | B9: Retail Brands | C9: 308925.81 | D9: 104897.76 | E9: 92330.61 | F9: 67512.2 | G9: 106366.9 | H9: 65628.67 | I9: 201577.09 | J9: 25941.66 | K9: 85585.84 | L9: 1058766.5 | M9: 0.1358
A10: 45900 | B10: Retail Brands | C10: 319518.54 | D10: 109414.46 | E10: 254253.61 | F10: 122364.67 | G10: 166413.09 | H10: 20958.46 | I10: 5250.9 | J10: 383249.81 | K10: 162064.52 | L10: 1543488 | M10: 0.195
A11: 45930 | B11: Retail Brands | C11: 326343.46 | D11: 138443.02 | E11: 55754.49 | F11: 47103.46 | G11: 19032.13 | H11: 162328.01 | I11: 183987.94 | J11: 136199.46 | K11: 213982.89 | L11: 1283174.9 | M11: 0.1623
A12: 45961 | B12: Retail Brands | C12: 334994.19 | D12: 193137.47 | E12: 34778.34 | F12: 236678.7 | G12: 65937.35 | H12: 93440.15 | I12: 62274.28 | J12: 136224.19 | K12: 174329.74 | L12: 1331794.4 | M12: 0.1648
A13: 45991 | B13: Retail Brands | C13: 313400 | D13: 88794.63 | E13: 57010.5 | F13: 432133.79 | G13: 83409.46 | H13: 133689.46 | I13: 22225.63 | J13: 83015.93 | K13: 20770.71 | L13: 1234450.1 | M13: 0.1576
... A49: 45991 | B49: All Divisions | C49: 513980 | D49: 366089.84 | E49: 162552.71 | F49: 483654.63 | G49: 184592.73 | H49: 341210.26 | I49: 47967.65 | J49: 262704.68 | K49: 375514.46 | L49: 2738267 | M49: 0.1533

Sheet Concentration_ADO_DSO
A1: Division | B1: AsOfDate | C1: Customer | D1: Current Concentration % | E1: Avg TTM Concentration % | F1: Variance Concentration (pp) | G1: Current ADO (Days) | H1: Avg TTM ADO (Days) | I1: Variance ADO (Days) | J1: Current DSO (Days) | K1: Avg TTM DSO (Days) | L1: Variance DSO (Days)
A2: All Divisions | B2: 45991 | C2: Cedar Grove Food Group | D2: 0.0555 | E2: 0.0408 | F2: 1.47 | G2: 21.7 | H2: 21.7 | I2: 0 | J2: 45.4 | K2: 42.9 | L2: 2.5
A3: All Divisions | B3: 45991 | C3: Summit Crest Baking | D3: 0.0535 | E3: 0.0227 | F3: 3.08 | G3: 23.6 | H3: 20.6 | I3: 3 | J3: 45.6 | K3: 43.3 | L3: 2.3
A4: All Divisions | B4: 45991 | C4: Premier Baking Goods | D4: 0.0506 | E4: 0.0359 | F4: 1.47 | G4: 21 | H4: 20.5 | I4: 0.4 | J4: 45.5 | K4: 43 | L4: 2.5
A5: All Divisions | B5: 45991 | C5: Premium Dessert Partners | D5: 0.0366 | E5: 0.0319 | F5: 0.47 | G5: 21.4 | H5: 21.7 | I5: -0.4 | J5: 45.9 | K5: 43.1 | L5: 2.8
A6: All Divisions | B6: 45991 | C6: Signature Kitchens Retail | D6: 0.0355 | E6: 0.0331 | F6: 0.23 | G6: 20.9 | H6: 21.7 | I6: -0.7 | J6: 45.9 | K6: 43.1 | L6: 2.8
A7: All Divisions | B7: 45991 | C7: Lighthouse Grocery Partners | D7: 0.0348 | E7: 0.0187 | F7: 1.61 | G7: 25.8 | H7: 20.7 | I7: 5.1 | J7: 46.1 | K7: 43.4 | L7: 2.7
A8: All Divisions | B8: 45991 | C8: Holiday Baking Supply | D8: 0.0342 | E8: 0.0308 | F8: 0.34 | G8: 25.9 | H8: 21.3 | I8: 4.6 | J8: 46.1 | K8: 43.1 | L8: 3
A9: All Divisions | B9: 45991 | C9: Crown Confections | D9: 0.0334 | E9: 0.0285 | F9: 0.49 | G9: 18.6 | H9: 20.8 | I9: -2.3 | J9: 45.9 | K9: 43.1 | L9: 2.7
A10: All Divisions | B10: 45991 | C10: Crescent Confections | D10: 0.0334 | E10: 0.023 | F10: 1.04 | G10: 22.7 | H10: 22.4 | I10: 0.3 | J10: 46 | K10: 43.3 | L10: 2.7
A11: All Divisions | B11: 45991 | C11: SweetTreat Markets | D11: 0.033 | E11: 0.0269 | F11: 0.61 | G11: 24.6 | H11: 21 | I11: 3.6 | J11: 46.1 | K11: 43.2 | L11: 2.9
A12: All Divisions | B12: 45991 | C12: Festive Food Group | D12: 0.0274 | E12: 0.0345 | F12: -0.71 | G12: 20.7 | H12: 22.3 | I12: -1.5 | J12: 46.1 | K12: 43.1 | L12: 3
A13: All Divisions | B13: 45991 | C13: CloverLane Foods | D13: 0.0267 | E13: 0.0356 | F13: -0.89 | G13: 18.9 | H13: 21 | I13: -2.2 | J13: 46.1 | K13: 43 | L13: 3.1
... A81: Retail Brands | B81: 45991 | C81: Golden Spoon Distributing | D81: 0.0013 | E81: 0.0314 | F81: -3.01 | G81: 18.3 | H81: 21.6 | I81: -3.3 | J81: 54.2 | K81: 47.7 | L81: 6.5

Sheet Inveentory>>>

Sheet Finished Goods >>>

Sheet FG_Inventory_Metrics
A1: InventoryType | B1: Division | C1: AsOfDate | D1: TotalInventory | E1: IneligibleInventory | F1: AvailableInventory | G1: IneligiblePctOfInventory
A2: Finished Goods | B2: Foodservice | C2: 45657 | D2: 4940184 | E2: 395214.72 | F2: 4544969.3 | G2: 0.08
A3: Finished Goods | B3: Foodservice | C3: 45688 | D3: 4945476.6 | E3: 395638.15 | F3: 4549838.4 | G3: 0.080000005
A4: Finished Goods | B4: Foodservice | C4: 45716 | D4: 5097956.6 | E4: 407836.52 | F4: 4690120 | G4: 0.079999999
A5: Finished Goods | B5: Foodservice | C5: 45747 | D5: 4798627.2 | E5: 383890.18 | F5: 4414737 | G5: 0.080000001
A6: Finished Goods | B6: Foodservice | C6: 45777 | D6: 5130043.5 | E6: 410403.46 | F6: 4719640 | G6: 0.079999996
A7: Finished Goods | B7: Foodservice | C7: 45808 | D7: 5118072.2 | E7: 409445.78 | F7: 4708626.5 | G7: 0.08
A8: Finished Goods | B8: Foodservice | C8: 45838 | D8: 5078523.7 | E8: 406281.89 | F8: 4672241.8 | G8: 0.079999999
A9: Finished Goods | B9: Foodservice | C9: 45869 | D9: 4960085 | E9: 396806.8 | F9: 4563278.2 | G9: 0.08
A10: Finished Goods | B10: Foodservice | C10: 45900 | D10: 4714838.3 | E10: 377187.07 | F10: 4337651.2 | G10: 0.080000002
A11: Finished Goods | B11: Foodservice | C11: 45930 | D11: 4964355.1 | E11: 397148.41 | F11: 4567206.7 | G11: 0.080000001
A12: Finished Goods | B12: Foodservice | C12: 45961 | D12: 4775615.8 | E12: 382049.26 | F12: 4393566.5 | G12: 0.079999999
A13: Finished Goods | B13: Foodservice | C13: 45991 | D13: 4730840 | E13: 378467.21 | F13: 4352372.8 | G13: 0.080000003
... A49: Finished Goods | B49: All Divisions | C49: 45991 | D49: 17244592 | E49: 1379567.4 | F49: 15865024 | G49: 0.080000002

Sheet FG_Ineligible_detail
A1: Date | B1: InventoryType | C1: Division | D1: Slow-Moving/Obsolete | E1: Aged | F1: Off Site | G1: Consigned | H1: In-Transit | I1: Damaged/Non-Saleable | J1: Total Ineligible | K1: Ineligible % of Inventory
A2: 45657 | B2: Finished Goods | C2: Foodservice | D2: 64795.154 | E2: 20518.62 | F2: 20616.134 | G2: 225376.53 | H2: 32655.736 | I2: 31252.544 | J2: 395214.72 | K2: 0.08
A3: 45688 | B3: Finished Goods | C3: Foodservice | D3: 83343.77 | E3: 121729.18 | F3: 78814.716 | G3: 46409.247 | H3: 24319.441 | I3: 41021.8 | J3: 395638.15 | K3: 0.080000005
A4: 45716 | B4: Finished Goods | C4: Foodservice | D4: 74609.749 | E4: 17891.191 | F4: 9401.0042 | G4: 14721.567 | H4: 101994.34 | I4: 189218.67 | J4: 407836.52 | K4: 0.079999999
A5: 45747 | B5: Finished Goods | C5: Foodservice | D5: 34776.923 | E5: 71565.988 | F5: 163055.35 | G5: 57266.419 | H5: 5639.7381 | I5: 51585.762 | J5: 383890.18 | K5: 0.080000001
A6: 45777 | B6: Finished Goods | C6: Foodservice | D6: 92624.706 | E6: 75985.733 | F6: 23035.947 | G6: 30670.589 | H6: 107903.16 | I6: 80183.323 | J6: 410403.46 | K6: 0.079999996
A7: 45808 | B7: Finished Goods | C7: Foodservice | D7: 5730.7233 | E7: 109872.75 | F7: 6144.2595 | G7: 143325.42 | H7: 82116.364 | I7: 62256.259 | J7: 409445.78 | K7: 0.08
A8: 45838 | B8: Finished Goods | C8: Foodservice | D8: 51006.587 | E8: 124875.41 | F8: 66020.75 | G8: 52075.855 | H8: 14478.128 | I8: 97825.16 | J8: 406281.89 | K8: 0.079999999
A9: 45869 | B9: Finished Goods | C9: Foodservice | D9: 199112.01 | E9: 9363.6281 | F9: 84534.714 | G9: 4545.6128 | H9: 53558.278 | I9: 45692.561 | J9: 396806.8 | K9: 0.08
A10: 45900 | B10: Finished Goods | C10: Foodservice | D10: 19847.126 | E10: 282210.56 | F10: 11654.83 | G10: 30805.45 | H10: 13165.885 | I10: 19503.218 | J10: 377187.07 | K10: 0.080000002
A11: 45930 | B11: Finished Goods | C11: Foodservice | D11: 60605.393 | E11: 137783.58 | F11: 101910.6 | G11: 1357.6597 | H11: 27733.266 | I11: 67757.912 | J11: 397148.41 | K11: 0.080000001
A12: 45961 | B12: Finished Goods | C12: Foodservice | D12: 28651.65 | E12: 29876.917 | F12: 157541.63 | G12: 68896.808 | H12: 44912.015 | I12: 52170.239 | J12: 382049.26 | K12: 0.079999999
A13: 45991 | B13: Finished Goods | C13: Foodservice | D13: 62600.776 | E13: 40959.838 | F13: 143670.68 | G13: 8819.1549 | H13: 70390.762 | I13: 52025.999 | J13: 378467.21 | K13: 0.080000003
... A49: 45991 | B49: Finished Goods | C49: All Divisions | D49: 33378.739 | E49: 37981.554 | F49: 8610.6304 | G49: 570872.34 | H49: 361817.67 | I49: 366906.42 | J49: 1379567.4 | K49: 0.080000002

Sheet FG_Composition
A1: Division | B1: AsOfDate | C1: FG_Available | D1: FG_0_13 | E1: FG_13_26 | F1: FG_26_39 | G1: FG_39_52 | H1: FG_52Plus | I1: FG_NoSales | J1: InlinePct | K1: ExcessPct
A2: All Divisions | B2: 45657 | C2: 16120044 | D2: 7445436.5 | E2: 5028628.4 | F2: 1579218.7 | G2: 1084271.5 | H2: 504133.84 | I2: 478355.22 | J2: 0.7738 | K2: 0.2262
A3: All Divisions | B3: 45688 | C3: 15441786 | D3: 7619961.5 | E3: 5396514.4 | F3: 1131758.8 | G3: 720398.52 | H3: 309135.24 | I3: 264017.37 | J3: 0.8429 | K3: 0.1571
A4: All Divisions | B4: 45716 | C4: 15428443 | D4: 7440460.8 | E4: 4984796.1 | F4: 1431912.9 | G4: 858939.58 | H4: 534031.29 | I4: 178302.1 | J4: 0.8053 | K4: 0.1947
A5: All Divisions | B5: 45747 | C5: 15064190 | D5: 7419375.7 | E5: 4822729.8 | F5: 1332672.1 | G5: 880379.28 | H5: 465750.52 | I5: 143282.31 | J5: 0.8127 | K5: 0.1873
A6: All Divisions | B6: 45777 | C6: 15772068 | D6: 7617677.9 | E6: 5127327.8 | F6: 1412684.6 | G6: 1016260.2 | H6: 455386.92 | I6: 142730.3 | J6: 0.8081 | K6: 0.1919
A7: All Divisions | B7: 45808 | C7: 15545929 | D7: 8329851.7 | E7: 5229786.9 | F7: 1035236.5 | G7: 597367.37 | H7: 262510.57 | I7: 91175.41 | J7: 0.8722 | K7: 0.1278
A8: All Divisions | B8: 45838 | C8: 15771837 | D8: 8294492.6 | E8: 5454196.3 | F8: 859694.89 | G8: 607878.55 | H8: 357005.75 | I8: 198568.46 | J8: 0.8717 | K8: 0.1283
A9: All Divisions | B9: 45869 | C9: 15004598 | D9: 7369544.6 | E9: 4710083.3 | F9: 1422883 | G9: 892364.13 | H9: 510413.01 | I9: 99310.34 | J9: 0.8051 | K9: 0.1949
A10: All Divisions | B10: 45900 | C10: 15077369 | D10: 7665690.3 | E10: 5567647.2 | F10: 915384.22 | G10: 549286.23 | H10: 228669.46 | I10: 150691.23 | J10: 0.8777 | K10: 0.1223
A11: All Divisions | B11: 45930 | C11: 14999478 | D11: 7955670.8 | E11: 5035562.5 | F11: 874644.36 | G11: 627015.18 | H11: 337835.62 | I11: 168749.58 | J11: 0.8661 | K11: 0.1339
A12: All Divisions | B12: 45961 | C12: 14911970 | D12: 7506980.5 | E12: 4800138.9 | F12: 1138181.3 | G12: 758040.51 | H12: 379046.45 | I12: 329582.06 | J12: 0.8253 | K12: 0.1747
A13: All Divisions | B13: 45991 | C13: 15865024 | D13: 8214046.8 | E13: 5472991.2 | F13: 1080555.2 | G13: 650050.2 | H13: 320045.97 | I13: 127334.9 | J13: 0.8627 | K13: 0.1373
... A49: Retail Brands | B49: 45991 | C49: 8465246.8 | D49: 4197787.3 | E49: 3225910.1 | F49: 566649.35 | G49: 314103.12 | H49: 125780.39 | I49: 35016.46 | J49: 0.877 | K49: 0.123

Sheet FG_Inline_Category_Analysis
A1: Division | B1: AsOfDate | C1: Category | D1: FG_Total | E1: FG_Ineligible | F1: FG_Available | G1: % of Available | H1: Sales | I1: COGS | J1: GM | K1: GM% | L1: Weeks_of_Supply
A2: All Divisions | B2: 45657 | C2: Baking Decorations | D2: 1514328.8 | E2: 121146.29 | F2: 1393182.4 | G2: 0.0864 | H2: 1086727.6 | I2: 812703.92 | J2: 274023.71 | K2: 0.2522 | L2: 5.51
A3: All Divisions | B3: 45657 | C3: Baking Mixes | D3: 3154593.5 | E3: 252367.47 | F3: 2902226 | G3: 0.18 | H3: 2281144.9 | I3: 1716533.8 | J3: 564611.1 | K3: 0.2475 | L3: 5.47
A4: All Divisions | B4: 45657 | C4: Bulk Wholesale Items | D4: 1523444.3 | E4: 121875.55 | F4: 1401568.7 | G4: 0.0869 | H4: 1266479 | I4: 998986.16 | J4: 267492.84 | K4: 0.2112 | L4: 4.76
A5: All Divisions | B5: 45657 | C5: Food Coloring & Dyes | D5: 2141592.8 | E5: 171327.42 | F5: 1970265.4 | G5: 0.1222 | H5: 1510431.6 | I5: 1125359.4 | J5: 385072.26 | K5: 0.2549 | L5: 5.61
A6: All Divisions | B6: 45657 | C6: Icings & Frostings | D6: 1379533.8 | E6: 110362.71 | F6: 1269171.1 | G6: 0.0787 | H6: 1011651.3 | I6: 765378.19 | J6: 246273.08 | K6: 0.2434 | L6: 5.39
A7: All Divisions | B7: 45657 | C7: Molds & Specialty Tools | D7: 409342 | E7: 32747.36 | F7: 376594.63 | G7: 0.0234 | H7: 332513.06 | I7: 264113.81 | J7: 68399.27 | K7: 0.2057 | L7: 4.87
A8: All Divisions | B8: 45657 | C8: Other | D8: 1611623.5 | E8: 128929.88 | F8: 1482693.6 | G8: 0.092 | H8: 1150629.2 | I8: 859924.08 | J8: 290705.1 | K8: 0.2526 | L8: 5.54
A9: All Divisions | B9: 45657 | C9: Packaging Components | D9: 1176527 | E9: 94122.16 | F9: 1082404.8 | G9: 0.0671 | H9: 880074.74 | I9: 675185.15 | J9: 204889.6 | K9: 0.2328 | L9: 5.29
A10: All Divisions | B10: 45657 | C10: Seasonal / Holiday Items | D10: 1681201.9 | E10: 134496.15 | F10: 1546705.8 | G10: 0.0959 | H10: 1260439 | I10: 970562.72 | J10: 289876.25 | K10: 0.23 | L10: 5.28
A11: All Divisions | B11: 45657 | C11: Sprinkles & Toppings | D11: 2929599.6 | E11: 234367.97 | F11: 2695231.6 | G11: 0.1672 | H11: 2083329 | I11: 1554335.7 | J11: 528993.26 | K11: 0.2539 | L11: 5.56
A12: All Divisions | B12: 45688 | C12: Baking Decorations | D12: 2332640.2 | E12: 186611.23 | F12: 2146029 | G12: 0.139 | H12: 1661556.9 | I12: 1239515.1 | J12: 422041.84 | K12: 0.254 | L12: 5.55
A13: All Divisions | B13: 45688 | C13: Baking Mixes | D13: 2829148.2 | E13: 226331.86 | F13: 2602816.3 | G13: 0.1686 | H13: 1972557.4 | I13: 1468434 | J13: 504123.44 | K13: 0.2556 | L13: 5.67
... A481: Retail Brands | B481: 45991 | C481: Sprinkles & Toppings | D481: 1834792.3 | E481: 146783.38 | F481: 1688008.9 | G481: 0.1994 | H481: 851312.78 | I481: 579233.22 | J481: 272079.56 | K481: 0.3196 | L481: 8.53

Sheet Sales_GM_Trend
A1: Division | B1: AsOfDate | C1: NetSales | D1: GrossMarginPct | E1: GrossMarginDollars | F1: TTM_Sales | G1: TTM_Sales_Prior | H1: Trend_TTM_Pct | I1: MA3 | J1: MA3_prior | K1: Trend_3M_Pct
A2: All Divisions | B2: 45657 | C2: 12863419 | D2: 0.2426 | E2: 3120513.1 | F2: 1.4073727e+08 | G2: 1.5083232e+08 | H2: -0.0669 | I2: 11994646 | J2: 11521746 | K2: 0.041
A3: All Divisions | B3: 45688 | C3: 11950485 | D3: 0.2532 | E3: 3025572.3 | F3: 1.4101908e+08 | G3: 1.4995987e+08 | H3: -0.0596 | I3: 12036725 | J3: 11782030 | K3: 0.0216
A4: All Divisions | B4: 45716 | C4: 12008506 | D4: 0.2359 | E4: 2833169.9 | F4: 1.4133147e+08 | G4: 1.4913229e+08 | H4: -0.0523 | I4: 12274137 | J4: 11780553 | K4: 0.0419
A5: All Divisions | B5: 45747 | C5: 11949467 | D5: 0.2444 | E5: 2920972.5 | F5: 1.4160776e+08 | G5: 1.4826327e+08 | H5: -0.0449 | I5: 11969486 | J5: 11994646 | K5: -0.0021
A6: All Divisions | B6: 45777 | C6: 12134463 | D6: 0.2573 | E6: 3121669.7 | F6: 1.4177851e+08 | G6: 1.4766765e+08 | H6: -0.0399 | I6: 12030812 | J6: 12036725 | K6: -0.0005
A7: All Divisions | B7: 45808 | C7: 12007009 | D7: 0.2514 | E7: 3018453.4 | F7: 1.4215351e+08 | G7: 1.4670843e+08 | H7: -0.031 | I7: 12030313 | J7: 12274137 | K7: -0.0199
A8: All Divisions | B8: 45838 | C8: 11903993 | D8: 0.2466 | E8: 2936041.8 | F8: 1.425031e+08 | G8: 1.4565643e+08 | H8: -0.0216 | I8: 12015155 | J8: 11969486 | K8: 0.0038
A9: All Divisions | B9: 45869 | C9: 11403422 | D9: 0.2358 | E9: 2688835.1 | F9: 1.4286313e+08 | G9: 1.4408222e+08 | H9: -0.0085 | I9: 11771475 | J9: 12030812 | K9: -0.0216
A10: All Divisions | B10: 45900 | C10: 11621535 | D10: 0.2408 | E10: 2798908.6 | F10: 1.4318396e+08 | G10: 1.4278708e+08 | H10: 0.0028 | I10: 11642983 | J10: 12030313 | K10: -0.0322
A11: All Divisions | B11: 45930 | C11: 12474628 | D11: 0.2432 | E11: 3033714 | F11: 1.4343745e+08 | G11: 1.4242076e+08 | H11: 0.0071 | I11: 11833195 | J11: 12015155 | K11: -0.0151
A12: All Divisions | B12: 45961 | C12: 12180509 | D12: 0.2446 | E12: 2979278.1 | F12: 1.4379371e+08 | G12: 1.4166851e+08 | H12: 0.015 | I12: 12092224 | J12: 11771475 | K12: 0.0272
A13: All Divisions | B13: 45991 | C13: 11502563 | D13: 0.2369 | E13: 2724786.6 | F13: 144000000 | G13: 1.4043651e+08 | H13: 0.0254 | I13: 12052567 | J13: 11642983 | K13: 0.0352
... A49: Retail Brands | B49: 45991 | C49: 4269274.2 | D49: 0.3196 | E49: 1364571.1 | F49: 57064150 | G49: 55437663 | H49: 0.0293 | I49: 4635831.5 | J49: 4746335 | K49: -0.0233

Sheet FG_Inline_Excess_By_Category
A1: Division | B1: AsOfDate | C1: Category | D1: FG_Available | E1: Inline_Dollars | F1: Inline_Pct | G1: Excess_Dollars | H1: Excess_Pct
A2: All Divisions | B2: 45657 | C2: Baking Decorations | D2: 1393182.4 | E2: 1064326 | F2: 0.764 | G2: 328856.48 | H2: 0.236
A3: All Divisions | B3: 45657 | C3: Baking Mixes | D3: 2902226 | E3: 2237703.9 | F3: 0.771 | G3: 664522.09 | H3: 0.229
A4: All Divisions | B4: 45657 | C4: Bulk Wholesale Items | D4: 1401568.7 | E4: 1090706.4 | F4: 0.7782 | G4: 310862.3 | H4: 0.2218
A5: All Divisions | B5: 45657 | C5: Food Coloring & Dyes | D5: 1970265.4 | E5: 1514850.4 | F5: 0.7689 | G5: 455414.97 | H5: 0.2311
A6: All Divisions | B6: 45657 | C6: Icings & Frostings | D6: 1269171.1 | E6: 980095.85 | F6: 0.7722 | G6: 289075.23 | H6: 0.2278
A7: All Divisions | B7: 45657 | C7: Molds & Specialty Tools | D7: 376594.63 | E7: 305346.38 | F7: 0.8108 | G7: 71248.26 | H7: 0.1892
A8: All Divisions | B8: 45657 | C8: Other | D8: 1482693.6 | E8: 1136154.7 | F8: 0.7663 | G8: 346538.86 | H8: 0.2337
A9: All Divisions | B9: 45657 | C9: Packaging Components | D9: 1082404.8 | E9: 852698.53 | F9: 0.7878 | G9: 229706.32 | H9: 0.2122
A10: All Divisions | B10: 45657 | C10: Seasonal / Holiday Items | D10: 1546705.8 | E10: 1228282.8 | F10: 0.7941 | G10: 318423.01 | H10: 0.2059
A11: All Divisions | B11: 45657 | C11: Sprinkles & Toppings | D11: 2695231.6 | E11: 2063791.1 | F11: 0.7657 | G11: 631440.55 | H11: 0.2343
A12: All Divisions | B12: 45688 | C12: Baking Decorations | D12: 2146029 | E12: 1811322.4 | F12: 0.844 | G12: 334706.64 | H12: 0.156
A13: All Divisions | B13: 45688 | C13: Baking Mixes | D13: 2602816.3 | E13: 2178603.7 | F13: 0.837 | G13: 424212.6 | H13: 0.163
... A481: Retail Brands | B481: 45991 | C481: Sprinkles & Toppings | D481: 1688008.9 | E481: 1480383.8 | F481: 0.877 | G481: 207625.09 | H481: 0.123

Sheet Historical_Top_20_SKUs
A1: Division | B1: AsOfDate | C1: ItemNumber | D1: Category | E1: Description | F1: Cost | G1: % of Total | H1: COGS | I1: GM | J1: GM% | K1: WOS
A2: Retail Brands | B2: 45657 | C2: 356980 | D2: Bulk Wholesale Items | E2: Foodservice Icing Pail | F2: 270172.62 | G2: 0.033241 | H2: 1755756.5 | I2: 851231.86 | J2: 0.3265 | K2: 7.37
A3: Retail Brands | B3: 45688 | C3: 356980 | D3: Bulk Wholesale Items | E3: Foodservice Icing Pail | F3: 260897.63 | G3: 0.03401 | H3: 1695481.6 | I3: 822009.19 | J3: 0.3265 | K3: 7.31
A4: Retail Brands | B4: 45716 | C4: 356980 | D4: Bulk Wholesale Items | E4: Foodservice Icing Pail | F4: 296972.61 | G4: 0.04074 | H4: 1929920.2 | I4: 935670.49 | J4: 0.3265 | K4: 7.93
A5: Retail Brands | B5: 45747 | C5: 356980 | D5: Bulk Wholesale Items | E5: Foodservice Icing Pail | F5: 305012.04 | G5: 0.040777 | H5: 1982165.6 | I5: 961000.27 | J5: 0.3265 | K5: 7.6
A6: Retail Brands | B6: 45777 | C6: 356980 | D6: Bulk Wholesale Items | E6: Foodservice Icing Pail | F6: 256366.18 | G6: 0.033074 | H6: 1666033.3 | I6: 807731.95 | J6: 0.3265 | K6: 7.28
A7: Retail Brands | B7: 45808 | C7: 356980 | D7: Bulk Wholesale Items | E7: Foodservice Icing Pail | F7: 273244.88 | G7: 0.037028 | H7: 1775722 | I7: 860911.61 | J7: 0.3265 | K7: 7.73
A8: Retail Brands | B8: 45838 | C8: 356980 | D8: Bulk Wholesale Items | E8: Foodservice Icing Pail | F8: 294179.21 | G8: 0.036203 | H8: 1911766.8 | I8: 926869.33 | J8: 0.3265 | K8: 8.29
A9: Retail Brands | B9: 45869 | C9: 356980 | D9: Bulk Wholesale Items | E9: Foodservice Icing Pail | F9: 295242.51 | G9: 0.03969 | H9: 1918676.9 | I9: 930219.48 | J9: 0.3265 | K9: 7.82
A10: Retail Brands | B10: 45900 | C10: 356980 | D10: Bulk Wholesale Items | E10: Foodservice Icing Pail | F10: 264224.75 | G10: 0.036218 | H10: 1717103.4 | I10: 832491.94 | J10: 0.3265 | K10: 8.06
A11: Retail Brands | B11: 45930 | C11: 356980 | D11: Bulk Wholesale Items | E11: Foodservice Icing Pail | F11: 278497.78 | G11: 0.03852 | H11: 1809858.8 | I11: 877461.9 | J11: 0.3265 | K11: 8.37
A12: Retail Brands | B12: 45961 | C12: 356980 | D12: Bulk Wholesale Items | E12: Foodservice Icing Pail | F12: 207407.31 | G12: 0.027906 | H12: 1347866.9 | I12: 653477.43 | J12: 0.3265 | K12: 7.98
A13: Retail Brands | B13: 45991 | C13: 356980 | D13: Bulk Wholesale Items | E13: Foodservice Icing Pail | F13: 280587.86 | G13: 0.033146 | H13: 1823441.4 | I13: 884047.1 | J13: 0.3265 | K13: 7.04
... A1201: All Divisions | B1201: 45991 | C1201: 383382 | D1201: Seasonal / Holiday Items | E1201: Christmas Cookie Kit | F1201: 101126.57 | G1201: 0.006374 | H1201: 1298124.7 | I1201: 213465.74 | J1201: 0.1412 | K1201: 3.83

Sheet Raw Materials >>>

Sheet RM_Inventory_Metrics
A1: InventoryType | B1: Division | C1: AsOfDate | D1: TotalInventory | E1: IneligibleInventory | F1: AvailableInventory | G1: IneligiblePctOfInventory
A2: Raw Materials | B2: Foodservice | C2: 45657 | D2: 2440173 | E2: 332388.31 | F2: 2107784.7 | G2: 0.1362
A3: Raw Materials | B3: Foodservice | C3: 45688 | D3: 2645911.5 | E3: 624443.38 | F3: 2021468.1 | G3: 0.236
A4: Raw Materials | B4: Foodservice | C4: 45716 | D4: 2548736.9 | E4: 424340.06 | F4: 2124396.8 | G4: 0.1665
A5: Raw Materials | B5: Foodservice | C5: 45747 | D5: 2440178.3 | E5: 578344.11 | F5: 1861834.1 | G5: 0.237
A6: Raw Materials | B6: Foodservice | C6: 45777 | D6: 2552679.3 | E6: 336723.71 | F6: 2215955.5 | G6: 0.1319
A7: Raw Materials | B7: Foodservice | C7: 45808 | D7: 2492276.4 | E7: 378279.36 | F7: 2113997 | G7: 0.1518
A8: Raw Materials | B8: Foodservice | C8: 45838 | D8: 2558786.6 | E8: 427835.25 | F8: 2130951.4 | G8: 0.1672
A9: Raw Materials | B9: Foodservice | C9: 45869 | D9: 2599749.7 | E9: 331639.77 | F9: 2268109.9 | G9: 0.1276
A10: Raw Materials | B10: Foodservice | C10: 45900 | D10: 2540158.4 | E10: 537990.63 | F10: 2002167.8 | G10: 0.2118
A11: Raw Materials | B11: Foodservice | C11: 45930 | D11: 2699934.8 | E11: 563189.8 | F11: 2136745 | G11: 0.2086
A12: Raw Materials | B12: Foodservice | C12: 45961 | D12: 2686785.2 | E12: 613945.7 | F12: 2072839.5 | G12: 0.2285
A13: Raw Materials | B13: Foodservice | C13: 45991 | D13: 2665443 | E13: 537497.85 | F13: 2127945.2 | G13: 0.2017
... A49: Raw Materials | B49: All Divisions | C49: 45991 | D49: 8427622.3 | E49: 1531374.2 | F49: 6896248.2 | G49: 0.1817

Sheet RM_Ineligible_Overview
A1: Date | B1: InventoryType | C1: Division | D1: Slow-Moving/Obsolete | E1: Aged | F1: Off Site | G1: Consigned | H1: In-Transit | I1: Damaged/Non-Saleable | J1: Total Ineligible | K1: Ineligible % of Inventory
A2: 45657 | B2: Raw Materials | C2: Foodservice | D2: 18813.32 | E2: 52172.33 | F2: 167966.92 | G2: 24052.11 | H2: 59411.3 | I2: 9972.33 | J2: 332388.31 | K2: 0.1362
A3: 45688 | B3: Raw Materials | C3: Foodservice | D3: 80473.3 | E3: 18026.4 | F3: 324066.63 | G3: 35841.02 | H3: 162481.61 | I3: 3554.42 | J3: 624443.38 | K3: 0.236
A4: 45716 | B4: Raw Materials | C4: Foodservice | D4: 81693.92 | E4: 15043.02 | F4: 129462.12 | G4: 137529.6 | H4: 23181.63 | I4: 37429.77 | J4: 424340.06 | K4: 0.1665
A5: 45747 | B5: Raw Materials | C5: Foodservice | D5: 269572.03 | E5: 57646.54 | F5: 79195.93 | G5: 121882.26 | H5: 45142.35 | I5: 4905 | J5: 578344.11 | K5: 0.237
A6: 45777 | B6: Raw Materials | C6: Foodservice | D6: 66461.34 | E6: 14620.75 | F6: 79849.31 | G6: 35093.91 | H6: 82501.39 | I6: 58197.01 | J6: 336723.71 | K6: 0.1319
A7: 45808 | B7: Raw Materials | C7: Foodservice | D7: 1046.84 | E7: 22558.68 | F7: 10007.83 | G7: 273138.98 | H7: 4677.26 | I7: 66849.77 | J7: 378279.36 | K7: 0.1518
A8: 45838 | B8: Raw Materials | C8: Foodservice | D8: 801.49 | E8: 86709.08 | F8: 185787.77 | G8: 6570.4 | H8: 45170.08 | I8: 102796.43 | J8: 427835.25 | K8: 0.1672
A9: 45869 | B9: Raw Materials | C9: Foodservice | D9: 19281.16 | E9: 34609.4 | F9: 221679.59 | G9: 10804.57 | H9: 12351.58 | I9: 32913.47 | J9: 331639.77 | K9: 0.1276
A10: 45900 | B10: Raw Materials | C10: Foodservice | D10: 85807.49 | E10: 50745.5 | F10: 52680.55 | G10: 186425.5 | H10: 98736.63 | I10: 63594.96 | J10: 537990.63 | K10: 0.2118
A11: 45930 | B11: Raw Materials | C11: Foodservice | D11: 33661.02 | E11: 36546.82 | F11: 165076.41 | G11: 147538.53 | H11: 4202.98 | I11: 176164.04 | J11: 563189.8 | K11: 0.2086
A12: 45961 | B12: Raw Materials | C12: Foodservice | D12: 33184.41 | E12: 115120.4 | F12: 218597.55 | G12: 124571.4 | H12: 42497.57 | I12: 79974.37 | J12: 613945.7 | K12: 0.2285
A13: 45991 | B13: Raw Materials | C13: Foodservice | D13: 230908.03 | E13: 8613.71 | F13: 28574.36 | G13: 102331.66 | H13: 55695.71 | I13: 111374.38 | J13: 537497.85 | K13: 0.2017
... A49: 45991 | B49: Raw Materials | C49: All Divisions | D49: 753152.37 | E49: 13554.3 | F49: 131179.99 | G49: 24393.51 | H49: 220982.82 | I49: 388111.19 | J49: 1531374.2 | K49: 0.1817

Sheet RM_Category_History
A1: Date | B1: InventoryType | C1: Division | D1: Category | E1: TotalInventory | F1: IneligibleInventory | G1: AvailableInventory | H1: %Available
A2: 45657 | B2: Raw Materials | C2: Foodservice | D2: Sugar & Sweeteners | E2: 466605.45 | F2: 63558.69 | G2: 403046.76 | H2: 0.8638
A3: 45657 | B3: Raw Materials | C3: Foodservice | D3: Flours & Starches | E3: 524177.82 | F3: 71400.91 | G3: 452776.91 | H3: 0.8638
A4: 45657 | B4: Raw Materials | C4: Foodservice | D4: Oils & Shortenings | E4: 393594.13 | F4: 53613.45 | G4: 339980.68 | H4: 0.8638
A5: 45657 | B5: Raw Materials | C5: Foodservice | D5: Spices & Flavorings | E5: 181904.58 | F5: 24778.14 | G5: 157126.44 | H5: 0.8638
A6: 45657 | B6: Raw Materials | C6: Foodservice | D6: Colorants & Dyes | E6: 194385.32 | F6: 26478.21 | G6: 167907.12 | H6: 0.8638
A7: 45657 | B7: Raw Materials | C7: Foodservice | D7: Gums & Stabilizers | E7: 77960.04 | F7: 10619.33 | G7: 67340.71 | H7: 0.8638
A8: 45657 | B8: Raw Materials | C8: Foodservice | D8: Packaging Films | E8: 234882.53 | F8: 31994.54 | G8: 202887.99 | H8: 0.8638
A9: 45657 | B9: Raw Materials | C9: Foodservice | D9: Plastic Containers | E9: 134355.04 | F9: 18301.18 | G9: 116053.86 | H9: 0.8638
A10: 45657 | B10: Raw Materials | C10: Foodservice | D10: Corrugate & Cardboard | E10: 110054.28 | F10: 14991.05 | G10: 95063.23 | H10: 0.8638
A11: 45657 | B11: Raw Materials | C11: Foodservice | D11: Other RM | E11: 122253.83 | F11: 16652.81 | G11: 105601 | H11: 0.8638
A12: 45688 | B12: Raw Materials | C12: Foodservice | D12: Sugar & Sweeteners | E12: 446197.54 | F12: 105304.01 | G12: 340893.53 | H12: 0.764
A13: 45688 | B13: Raw Materials | C13: Foodservice | D13: Flours & Starches | E13: 569236.29 | F13: 134341.54 | G13: 434894.75 | H13: 0.764
... A481: 45991 | B481: Raw Materials | C481: All Divisions | D481: Other RM | E481: 178003.66 | F481: 32344.85 | G481: 145658.81 | H481: 0.8183

Sheet RM_Top20_History
A1: InventoryType | B1: Division | C1: AsOfDate | D1: SKU | E1: Category | F1: Description | G1: Amount | H1: Units | I1: $/Unit | J1: %Available
A2: Raw Materials | B2: Foodservice | C2: 45657 | D2: 551989 | E2: Sugar & Sweeteners | F2: Sugar & Sweeteners RM SKU 462 | G2: 136109.36 | H2: 65760 | I2: 2.07 | J2: 6.4575
A3: Raw Materials | B3: Foodservice | C3: 45688 | D3: 551989 | E3: Sugar & Sweeteners | F3: Sugar & Sweeteners RM SKU 462 | G3: 112448.54 | H3: 35929 | I3: 3.13 | J3: 5.5627
A4: Raw Materials | B4: Foodservice | C4: 45716 | D4: 551989 | E4: Sugar & Sweeteners | F4: Sugar & Sweeteners RM SKU 462 | G4: 108926.22 | H4: 19320 | I4: 5.64 | J4: 5.1274
A5: Raw Materials | B5: Foodservice | C5: 45747 | D5: 551989 | E5: Sugar & Sweeteners | F5: Sugar & Sweeteners RM SKU 462 | G5: 122009.5 | H5: 209779 | I5: 0.58 | J5: 6.5532
A6: Raw Materials | B6: Foodservice | C6: 45777 | D6: 551989 | E6: Sugar & Sweeteners | F6: Sugar & Sweeteners RM SKU 462 | G6: 108156.26 | H6: 16098 | I6: 6.72 | J6: 4.8808
A7: Raw Materials | B7: Foodservice | C7: 45808 | D7: 551989 | E7: Sugar & Sweeteners | F7: Sugar & Sweeteners RM SKU 462 | G7: 129562.27 | H7: 15631 | I7: 8.29 | J7: 6.1288
A8: Raw Materials | B8: Foodservice | C8: 45838 | D8: 551989 | E8: Sugar & Sweeteners | F8: Sugar & Sweeteners RM SKU 462 | G8: 113510.91 | H8: 17172 | I8: 6.61 | J8: 5.3268
A9: Raw Materials | B9: Foodservice | C9: 45869 | D9: 551989 | E9: Sugar & Sweeteners | F9: Sugar & Sweeteners RM SKU 462 | G9: 119993.79 | H9: 23543 | I9: 5.1 | J9: 5.2905
A10: Raw Materials | B10: Foodservice | C10: 45900 | D10: 551989 | E10: Sugar & Sweeteners | F10: Sugar & Sweeteners RM SKU 462 | G10: 107462.99 | H10: 27353 | I10: 3.93 | J10: 5.3673
A11: Raw Materials | B11: Foodservice | C11: 45930 | D11: 551989 | E11: Sugar & Sweeteners | F11: Sugar & Sweeteners RM SKU 462 | G11: 119647.04 | H11: 61221 | I11: 1.95 | J11: 5.5995
A12: Raw Materials | B12: Foodservice | C12: 45961 | D12: 551989 | E12: Sugar & Sweeteners | F12: Sugar & Sweeteners RM SKU 462 | G12: 102337.28 | H12: 12641 | I12: 8.1 | J12: 4.9371
A13: Raw Materials | B13: Foodservice | C13: 45991 | D13: 551989 | E13: Sugar & Sweeteners | F13: Sugar & Sweeteners RM SKU 462 | G13: 129117.92 | H13: 21831 | I13: 5.91 | J13: 6.0677
... A961: Raw Materials | B961: All Divisions | C961: 45991 | D961: 238890 | E961: Gums & Stabilizers | F961: Gums & Stabilizers RM SKU 457 | G961: 1072.11 | H961: 91 | I961: 11.84 | J961: 0.0155

Sheet Work-In-Process>>>

Sheet WIP_Inventory_Metrics
A1: InventoryType | B1: Division | C1: AsOfDate | D1: TotalInventory | E1: IneligibleInventory | F1: AvailableInventory | G1: IneligiblePctOfInventory
A2: Work-in-Process | B2: Foodservice | C2: 45657 | D2: 947817.68 | E2: 194573.72 | F2: 753243.96 | G2: 0.2053
A3: Work-in-Process | B3: Foodservice | C3: 45688 | D3: 972318.6 | E3: 137996.44 | F3: 834322.16 | G3: 0.1419
A4: Work-in-Process | B4: Foodservice | C4: 45716 | D4: 897537.72 | E4: 161514.13 | F4: 736023.6 | G4: 0.18
A5: Work-in-Process | B5: Foodservice | C5: 45747 | D5: 966814.89 | E5: 150719.06 | F5: 816095.84 | G5: 0.1559
A6: Work-in-Process | B6: Foodservice | C6: 45777 | D6: 923045.99 | E6: 180686.34 | F6: 742359.64 | G6: 0.1958
A7: Work-in-Process | B7: Foodservice | C7: 45808 | D7: 947115.35 | E7: 152474.76 | F7: 794640.59 | G7: 0.161
A8: Work-in-Process | B8: Foodservice | C8: 45838 | D8: 976522.4 | E8: 155913.15 | F8: 820609.25 | G8: 0.1597
A9: Work-in-Process | B9: Foodservice | C9: 45869 | D9: 979110.08 | E9: 244480.06 | F9: 734630.02 | G9: 0.2497
A10: Work-in-Process | B10: Foodservice | C10: 45900 | D10: 973876.33 | E10: 193188.16 | F10: 780688.18 | G10: 0.1984
A11: Work-in-Process | B11: Foodservice | C11: 45930 | D11: 1045888.1 | E11: 137320.79 | F11: 908567.28 | G11: 0.1313
A12: Work-in-Process | B12: Foodservice | C12: 45961 | D12: 1025823.7 | E12: 249717.48 | F12: 776106.18 | G12: 0.2434
A13: Work-in-Process | B13: Foodservice | C13: 45991 | D13: 1016837.2 | E13: 163094.94 | F13: 853742.25 | G13: 0.1604
... A49: Work-in-Process | B49: All Divisions | C49: 45991 | D49: 2964502.2 | E49: 507920.76 | F49: 2456581.5 | G49: 0.1713

Sheet WIP_Ineligible_Overview
A1: Date | B1: InventoryType | C1: Division | D1: Slow-Moving/Obsolete | E1: Aged | F1: Off Site | G1: Consigned | H1: In-Transit | I1: Damaged/Non-Saleable | J1: Total Ineligible | K1: Ineligible % of Inventory
A2: 45657 | B2: Work-in-Process | C2: Foodservice | D2: 22924.25 | E2: 59356.98 | F2: 28197.45 | G2: 763.04 | H2: 70347.63 | I2: 12984.37 | J2: 194573.72 | K2: 0.2053
A3: 45688 | B3: Work-in-Process | C3: Foodservice | D3: 61026.31 | E3: 6868.75 | F3: 5801.2 | G3: 15492.22 | H3: 2891.72 | I3: 45916.24 | J3: 137996.44 | K3: 0.1419
A4: 45716 | B4: Work-in-Process | C4: Foodservice | D4: 27245.85 | E4: 61044.72 | F4: 8932.01 | G4: 11144.35 | H4: 15466.55 | I4: 37680.65 | J4: 161514.13 | K4: 0.18
A5: 45747 | B5: Work-in-Process | C5: Foodservice | D5: 30214.36 | E5: 39463.38 | F5: 2095.33 | G5: 39424.77 | H5: 25465.09 | I5: 14056.13 | J5: 150719.06 | K5: 0.1559
A6: 45777 | B6: Work-in-Process | C6: Foodservice | D6: 4541.56 | E6: 12124.47 | F6: 55091.46 | G6: 61812.25 | H6: 17308.91 | I6: 29807.69 | J6: 180686.34 | K6: 0.1958
A7: 45808 | B7: Work-in-Process | C7: Foodservice | D7: 6705.61 | E7: 41078.22 | F7: 6513.62 | G7: 27819.34 | H7: 19434.71 | I7: 50923.26 | J7: 152474.76 | K7: 0.161
A8: 45838 | B8: Work-in-Process | C8: Foodservice | D8: 9851.46 | E8: 37956.98 | F8: 7477.87 | G8: 49969.07 | H8: 2559.91 | I8: 48097.86 | J8: 155913.15 | K8: 0.1597
A9: 45869 | B9: Work-in-Process | C9: Foodservice | D9: 14418.48 | E9: 12097.2 | F9: 6819.48 | G9: 48121.33 | H9: 117485.33 | I9: 45538.24 | J9: 244480.06 | K9: 0.2497
A10: 45900 | B10: Work-in-Process | C10: Foodservice | D10: 24322.69 | E10: 39405.21 | F10: 14584.86 | G10: 18644.17 | H10: 3863.17 | I10: 92368.06 | J10: 193188.16 | K10: 0.1984
A11: 45930 | B11: Work-in-Process | C11: Foodservice | D11: 18517.58 | E11: 5845.02 | F11: 31457.35 | G11: 13702.71 | H11: 23011.95 | I11: 44786.18 | J11: 137320.79 | K11: 0.1313
A12: 45961 | B12: Work-in-Process | C12: Foodservice | D12: 36475.78 | E12: 99157.61 | F12: 35227.12 | G12: 30001.66 | H12: 19548.75 | I12: 29306.56 | J12: 249717.48 | K12: 0.2434
A13: 45991 | B13: Work-in-Process | C13: Foodservice | D13: 40170.58 | E13: 13795 | F13: 37598.53 | G13: 1730.72 | H13: 52047.84 | I13: 17752.27 | J13: 163094.94 | K13: 0.1604
... A49: 45991 | B49: Work-in-Process | C49: All Divisions | D49: 134249.1 | E49: 56557.63 | F49: 172467.51 | G49: 78746.19 | H49: 60960.58 | I49: 4939.75 | J49: 507920.76 | K49: 0.1713

Sheet WIP_Category_History
A1: Date | B1: InventoryType | C1: Division | D1: Category | E1: TotalInventory | F1: IneligibleInventory | G1: AvailableInventory | H1: %Available
A2: 45657 | B2: Work-in-Process | C2: Foodservice | D2: Partially Processed Goods | E2: 156682.19 | F2: 32164.66 | G2: 124517.52 | H2: 0.7947
A3: 45657 | B3: Work-in-Process | C3: Foodservice | D3: Blending / Mixing Stage | E3: 144212.93 | F3: 29604.9 | G3: 114608.03 | H3: 0.7947
A4: 45657 | B4: Work-in-Process | C4: Foodservice | D4: Batch Prep / Staging | E4: 103963.52 | F4: 21342.26 | G4: 82621.26 | H4: 0.7947
A5: 45657 | B5: Work-in-Process | C5: Foodservice | D5: Flavor Additives In-Process | E5: 109888.74 | F5: 22558.62 | G5: 87330.12 | H5: 0.7947
A6: 45657 | B6: Work-in-Process | C6: Foodservice | D6: Coloring / Coating Stage | E6: 56804.44 | F6: 11661.16 | G6: 45143.28 | H6: 0.7947
A7: 45657 | B7: Work-in-Process | C7: Foodservice | D7: Packaging Prep Stage | E7: 118198.04 | F7: 24264.41 | G7: 93933.64 | H7: 0.7947
A8: 45657 | B8: Work-in-Process | C8: Foodservice | D8: Ingredient Prep (Cut / Ground / Melted) | E8: 76260.16 | F8: 15655.15 | G8: 60605.02 | H8: 0.7947
A9: 45657 | B9: Work-in-Process | C9: Foodservice | D9: In-Process Rework | E9: 48444.12 | F9: 9944.9 | G9: 38499.22 | H9: 0.7947
A10: 45657 | B10: Work-in-Process | C10: Foodservice | D10: Quality Hold | E10: 34093.39 | F10: 6998.9 | G10: 27094.5 | H10: 0.7947
A11: 45657 | B11: Work-in-Process | C11: Foodservice | D11: Other WIP | E11: 99270.15 | F11: 20378.76 | G11: 78891.37 | H11: 0.7947
A12: 45688 | B12: Work-in-Process | C12: Foodservice | D12: Partially Processed Goods | E12: 193492.81 | F12: 27461.49 | G12: 166031.32 | H12: 0.8581
A13: 45688 | B13: Work-in-Process | C13: Foodservice | D13: Blending / Mixing Stage | E13: 118546.89 | F13: 16824.78 | G13: 101722.1 | H13: 0.8581
... A481: 45991 | B481: Work-in-Process | C481: All Divisions | D481: Other WIP | E481: 202799.32 | F481: 34746.48 | G481: 168052.86 | H481: 0.8287

Sheet WIP_Top20_History
A1: InventoryType | B1: Division | C1: AsOfDate | D1: SKU | E1: Category | F1: Description | G1: Amount | H1: Units | I1: $/Unit | J1: %Available
A2: Work-in-Process | B2: Foodservice | C2: 45657 | D2: 798119 | E2: Other WIP | F2: Other WIP WIP SKU 472 | G2: 39960.01 | H2: 8287 | I2: 4.82 | J2: 5.3051
A3: Work-in-Process | B3: Foodservice | C3: 45688 | D3: 798119 | E3: Other WIP | F3: Other WIP WIP SKU 472 | G3: 52201.63 | H3: 8668 | I3: 6.02 | J3: 6.2568
A4: Work-in-Process | B4: Foodservice | C4: 45716 | D4: 798119 | E4: Other WIP | F4: Other WIP WIP SKU 472 | G4: 47279.82 | H4: 4989 | I4: 9.48 | J4: 6.4237
A5: Work-in-Process | B5: Foodservice | C5: 45747 | D5: 798119 | E5: Other WIP | F5: Other WIP WIP SKU 472 | G5: 35536.73 | H5: 1891 | I5: 18.79 | J5: 4.3545
A6: Work-in-Process | B6: Foodservice | C6: 45777 | D6: 798119 | E6: Other WIP | F6: Other WIP WIP SKU 472 | G6: 43743.52 | H6: 25676 | I6: 1.7 | J6: 5.8925
A7: Work-in-Process | B7: Foodservice | C7: 45808 | D7: 798119 | E7: Other WIP | F7: Other WIP WIP SKU 472 | G7: 40765.36 | H7: 11214 | I7: 3.64 | J7: 5.13
A8: Work-in-Process | B8: Foodservice | C8: 45838 | D8: 798119 | E8: Other WIP | F8: Other WIP WIP SKU 472 | G8: 43037.76 | H8: 3549 | I8: 12.13 | J8: 5.2446
A9: Work-in-Process | B9: Foodservice | C9: 45869 | D9: 798119 | E9: Other WIP | F9: Other WIP WIP SKU 472 | G9: 39561.91 | H9: 17687 | I9: 2.24 | J9: 5.3853
A10: Work-in-Process | B10: Foodservice | C10: 45900 | D10: 798119 | E10: Other WIP | F10: Other WIP WIP SKU 472 | G10: 40589 | H10: 2846 | I10: 14.26 | J10: 5.1991
A11: Work-in-Process | B11: Foodservice | C11: 45930 | D11: 798119 | E11: Other WIP | F11: Other WIP WIP SKU 472 | G11: 52975.24 | H11: 3527 | I11: 15.02 | J11: 5.8306
A12: Work-in-Process | B12: Foodservice | C12: 45961 | D12: 798119 | E12: Other WIP | F12: Other WIP WIP SKU 472 | G12: 41748.24 | H12: 2431 | I12: 17.18 | J12: 5.3792
A13: Work-in-Process | B13: Foodservice | C13: 45991 | D13: 798119 | E13: Other WIP | F13: Other WIP WIP SKU 472 | G13: 43213.02 | H13: 2848 | I13: 15.17 | J13: 5.0616
... A961: Work-in-Process | B961: All Divisions | C961: 45991 | D961: 136781 | E961: Flavor Additives In-Process | F961: Flavor Additives In-Process WIP SKU 572 | G961: 2093.04 | H961: 175 | I961: 11.95 | J961: 0.0852

Sheet Liquidation>>>

Sheet FG_Gross_Recovery_History
A1: AsOfDate | B1: Division | C1: Category | D1: Type | E1: Cost | F1: SellingPrice | G1: GrossRecovery | H1: Pct_of_Cost | I1: Pct_of_SP | J1: WOS | K1: GM%
A2: 45657 | B2: All Divisions | C2: Excess - Total | D2: Excess | E2: 3646088.1 | F2: 4822856.2 | G2: 1513669.5 | H2: 0.41514891 | I2: 0.31385333
A3: 45657 | B3: All Divisions | C3: Baking Decorations | D3: Inline | E3: 1064326 | F3: 1423276.3 | G3: 1153167.1 | H3: 1.0834717 | I3: 0.81022014 | J3: 5.51 | K3: 0.2522
A4: 45657 | B4: All Divisions | C4: Baking Mixes | D4: Inline | E4: 2237703.9 | F4: 2973692.9 | G4: 2400491.4 | H4: 1.0727476 | I4: 0.80724255 | J4: 5.47 | K4: 0.2475 | N4: =SUM(E486:E496) -> 15865024 | O4: =SUM(F486:F496) -> 20832192 | P4: =SUM(G486:G496) -> 15609730
A5: 45657 | B5: All Divisions | C5: Bulk Wholesale Items | D5: Inline | E5: 1090706.4 | F5: 1382741.4 | G5: 1148731.6 | H5: 1.0531996 | I5: 0.83076385 | J5: 4.76 | K5: 0.2112
A6: 45657 | B6: All Divisions | C6: Food Coloring & Dyes | D6: Inline | E6: 1514850.4 | F6: 2033083.4 | G6: 1644142.3 | H6: 1.0853496 | I6: 0.80869399 | J6: 5.61 | K6: 0.2549
A7: 45657 | B7: All Divisions | C7: Icings & Frostings | D7: Inline | E7: 980095.85 | F7: 1295395 | G7: 1055235.8 | H7: 1.076666 | I7: 0.81460546 | J7: 5.39 | K7: 0.2434
A8: 45657 | B8: All Divisions | C8: Molds & Specialty Tools | D8: Inline | E8: 305346.38 | F8: 384421.98 | G8: 310387.54 | H8: 1.0165096 | I8: 0.8074136 | J8: 4.87 | K8: 0.2057
A9: 45657 | B9: All Divisions | C9: Other | D9: Inline | E9: 1136154.7 | F9: 1520142.8 | G9: 1280085.3 | H9: 1.1266822 | I9: 0.84208227 | J9: 5.54 | K9: 0.2526
A10: 45657 | B10: All Divisions | C10: Packaging Components | D10: Inline | E10: 852698.53 | F10: 1111442.3 | G10: 924983.46 | H10: 1.084772 | I10: 0.83223705 | J10: 5.29 | K10: 0.2328
A11: 45657 | B11: All Divisions | C11: Seasonal / Holiday Items | D11: Inline | E11: 1228282.8 | F11: 1595172.4 | G11: 1271381.6 | H11: 1.0350887 | I11: 0.79701827 | J11: 5.28 | K11: 0.23
A12: 45657 | B12: All Divisions | C12: Sprinkles & Toppings | D12: Inline | E12: 2063791.1 | F12: 2766105.2 | G12: 2198780.7 | H12: 1.0654086 | I12: 0.79490133 | J12: 5.56 | K12: 0.2539
A13: 45657 | B13: Foodservice | C13: Excess - Total | D13: Excess | E13: 1126697.9 | F13: 1419372.5 | G13: 470667.63 | H13: 0.41774076 | I13: 0.33160262
A14: 45657 | B14: Foodservice | C14: Baking Decorations | D14: Inline | E14: 331011.79 | F14: 416996.46 | G14: 353459.42 | H14: 1.0678152 | I14: 0.84763171 | J14: 4.48 | K14: 0.2062
A15: 45657 | B15: Foodservice | C15: Baking Mixes | D15: Inline | E15: 587943.7 | F15: 740669.82 | G15: 624176.64 | H15: 1.0616265 | I15: 0.84271915 | J15: 4.48 | K15: 0.2062
A16: 45657 | B16: Foodservice | C16: Bulk Wholesale Items | D16: Inline | E16: 611762.68 | F16: 770676.09 | G16: 652970.68 | H16: 1.0673594 | I16: 0.84726993 | J16: 4.48 | K16: 0.2062
A17: 45657 | B17: Foodservice | C17: Food Coloring & Dyes | D17: Inline | E17: 336833.74 | F17: 424330.74 | G17: 361201.41 | H17: 1.0723433 | I17: 0.85122613 | J17: 4.48 | K17: 0.2062
A18: 45657 | B18: Foodservice | C18: Icings & Frostings | D18: Inline | E18: 280462.5 | F18: 353316.33 | G18: 300246.63 | H18: 1.0705411 | I18: 0.84979551 | J18: 4.48 | K18: 0.2062
A19: 45657 | B19: Foodservice | C19: Molds & Specialty Tools | D19: Inline | E19: 59848.38 | F19: 75394.785 | G19: 62921.254 | H19: 1.0513443 | I19: 0.83455711 | J19: 4.48 | K19: 0.2062
A20: 45657 | B20: Foodservice | C20: Other | D20: Inline | E20: 313920.73 | F20: 395465.77 | G20: 334546.74 | H20: 1.0657045 | I20: 0.84595625 | J20: 4.48 | K20: 0.2062
A21: 45657 | B21: Foodservice | C21: Packaging Components | D21: Inline | E21: 163437.27 | F21: 205892.25 | G21: 172719.04 | H21: 1.056791 | I21: 0.83888071 | J21: 4.48 | K21: 0.2062
A22: 45657 | B22: Foodservice | C22: Seasonal / Holiday Items | D22: Inline | E22: 171891.59 | F22: 216542.69 | G22: 180303.6 | H22: 1.0489379 | I22: 0.83264691 | J22: 4.48 | K22: 0.2062
A23: 45657 | B23: Foodservice | C23: Sprinkles & Toppings | D23: Inline | E23: 561159.03 | F23: 706927.48 | G23: 582699.33 | H23: 1.0383854 | I23: 0.82427031 | J23: 4.48 | K23: 0.2062
A24: 45657 | B24: Private Label | C24: Excess - Total | D24: Excess | E24: 487450.5 | F24: 590491.22 | G24: 188845.13 | H24: 0.38741396 | I24: 0.31981022
A25: 45657 | B25: Private Label | C25: Baking Decorations | D25: Inline | E25: 146380.22 | F25: 177323.1 | G25: 144123.73 | H25: 0.98458471 | I25: 0.81277468 | J25: 4.5 | K25: 0.1745
A26: 45657 | B26: Private Label | C26: Baking Mixes | D26: Inline | E26: 469563.73 | F26: 568823.42 | G26: 481704.99 | H26: 1.0258565 | I26: 0.84684451 | J26: 4.5 | K26: 0.1745
A27: 45657 | B27: Private Label | C27: Bulk Wholesale Items | D27: Inline | E27: 299021.53 | F27: 362230.81 | G27: 308623.42 | H27: 1.032111 | I27: 0.85200767 | J27: 4.5 | K27: 0.1745
A28: 45657 | B28: Private Label | C28: Food Coloring & Dyes | D28: Inline | E28: 286285.97 | F28: 346803.11 | G28: 284950.63 | H28: 0.99533564 | I28: 0.82164957 | J28: 4.5 | K28: 0.1745
A29: 45657 | B29: Private Label | C29: Icings & Frostings | D29: Inline | E29: 216898.77 | F29: 262748.36 | G29: 217857.46 | H29: 1.00442 | I29: 0.82914871 | J29: 4.5 | K29: 0.1745
A30: 45657 | B30: Private Label | C30: Molds & Specialty Tools | D30: Inline | E30: 179731.17 | F30: 217724.01 | G30: 177906.14 | H30: 0.9898458 | I30: 0.81711771 | J30: 4.5 | K30: 0.1745
A31: 45657 | B31: Private Label | C31: Other | D31: Inline | E31: 183879.65 | F31: 222749.42 | G31: 189049.72 | H31: 1.0281166 | I31: 0.84871024 | J31: 4.5 | K31: 0.1745
A32: 45657 | B32: Private Label | C32: Packaging Components | D32: Inline | E32: 319710.31 | F32: 387292.93 | G32: 317275.39 | H32: 0.99238397 | I32: 0.81921297 | J32: 4.5 | K32: 0.1745
A33: 45657 | B33: Private Label | C33: Seasonal / Holiday Items | D33: Inline | E33: 535822.38 | F33: 649088.29 | G33: 549081.16 | H33: 1.0247447 | I33: 0.84592677 | J33: 4.5 | K33: 0.1745
A34: 45657 | B34: Private Label | C34: Sprinkles & Toppings | D34: Inline | E34: 322571.91 | F34: 390759.43 | G34: 331221.56 | H34: 1.0268146 | I34: 0.84763548 | J34: 4.5 | K34: 0.1745
A35: 45657 | B35: Retail Brands | C35: Excess - Total | D35: Excess | E35: 2031939.7 | F35: 2970672 | G35: 885349.41 | H35: 0.43571638 | I35: 0.29803001
A36: 45657 | B36: Retail Brands | C36: Baking Decorations | D36: Inline | E36: 586933.97 | F36: 858090.6 | G36: 713949.71 | H36: 1.2164055 | I36: 0.83202136 | J36: 6.71 | K36: 0.316
A37: 45657 | B37: Retail Brands | C37: Baking Mixes | D37: Inline | E37: 1180196.5 | F37: 1725433.4 | G37: 1360291.4 | H37: 1.1525974 | I37: 0.78837664 | J37: 6.71 | K37: 0.316
A38: 45657 | B38: Retail Brands | C38: Bulk Wholesale Items | D38: Inline | E38: 179922.21 | F38: 263044.17 | G38: 215947.1 | H38: 1.2002248 | I38: 0.82095379 | J38: 6.71 | K38: 0.316
A39: 45657 | B39: Retail Brands | C39: Food Coloring & Dyes | D39: Inline | E39: 891730.71 | F39: 1303699.9 | G39: 1001778.9 | H39: 1.1234096 | I39: 0.76841218 | J39: 6.71 | K39: 0.316
A40: 45657 | B40: Retail Brands | C40: Icings & Frostings | D40: Inline | E40: 482734.58 | F40: 705752.31 | G40: 580781.03 | H40: 1.2031063 | I40: 0.82292473 | J40: 6.71 | K40: 0.316
...

Sheet WIP_Recovery
A1: Date | B1: InventoryType | C1: Division | D1: Category | E1: TotalInventory | F1: IneligibleInventory | G1: AvailableInventory | H1: %Available | I1: RecoveryPct | J1: GrossRecovery
A2: 45657 | B2: Work-in-Process | C2: Foodservice | D2: Partially Processed Goods | E2: 156682.19 | F2: 32164.66 | G2: 124517.52 | H2: 0.7947 | I2: 0.2 | J2: 24903.504
A3: 45657 | B3: Work-in-Process | C3: Foodservice | D3: Blending / Mixing Stage | E3: 144212.93 | F3: 29604.9 | G3: 114608.03 | H3: 0.7947 | I3: 0.2 | J3: 22921.606
A4: 45657 | B4: Work-in-Process | C4: Foodservice | D4: Batch Prep / Staging | E4: 103963.52 | F4: 21342.26 | G4: 82621.26 | H4: 0.7947 | I4: 0.2 | J4: 16524.252
A5: 45657 | B5: Work-in-Process | C5: Foodservice | D5: Flavor Additives In-Process | E5: 109888.74 | F5: 22558.62 | G5: 87330.12 | H5: 0.7947 | I5: 0.15 | J5: 13099.518
A6: 45657 | B6: Work-in-Process | C6: Foodservice | D6: Coloring / Coating Stage | E6: 56804.44 | F6: 11661.16 | G6: 45143.28 | H6: 0.7947 | I6: 0.1 | J6: 4514.328
